Workbook

Sheet SETTINGS
A1: ⚙ SYSTEM SETTINGS – Cost, Margin & Commission Configuration
A2: Change the values in the BLUE cells to configure the system
A4: PARAMETER | B4: VALUE | C4: UNIT | D4: NOTES
A5: Minimum Approval Margin % | B5: 15 | C5: % | D5: Orders BELOW this margin % will be marked DISAPPROVED
A6: Warning Margin % (amber zone) | B6: 20 | C6: % | D6: Orders between Warning % and Approval % get an AMBER WARNING
A7: Sales Agent Commission % | B7: 10 | C7: % of Margin ₹ | D7: Agent earns this % of the margin amount on approved orders
A8: Default Currency Symbol | B8: ₹ | D8: Used in order sheet for display
A9: GST / Tax Rate % | B9: 18 | C9: % | D9: Applied on top of sale price if needed
A12: COLOUR LEGEND
A13: Yellow cells = Input values you can change
A14: Green background = APPROVED order
A15: Amber background = WARNING – margin is low
A16: Red background = DISAPPROVED – below minimum margin
A17: Blue text = User-entered input
A18: Black text = Formula (do not edit)

Sheet COST TABLE
A1: COST TABLE – Cost per Unit (₹) by Product & Quantity
A2: 📥 IMPORT ZONE: Paste your CSV data below (starting row 4) – Product Code in column A, costs in quantity columns. Column B is Product Description (optional).
A3: PRODUCT CODE | B3: DESCRIPTION | C3: 700 | D3: 1000 | E3: 1500 | F3: 2000 | G3: 3000 | H3: 3500 | I3: 4000 | J3: 5000 | K3: 6000 | L3: 8000 | M3: 9500 | N3: 10000 | O3: 12000 | P3: 15000 | Q3: 20000 | R3: 30000 | S3: 40000 | T3: 50000
A4: STRM
A5: ST175
A6: ST1575
A7: ST151
A8: ST125175
A9: ST3.2*1.6
A10: ST5*8
A11: ST1*3
A12: ST1*4
A13: ST1*2.5
A14: ST6*4
A15: ST4*2
... A36: EN10045

Sheet ORDER ENTRY
A1: ORDER ENTRY – Cost Lookup, Margin Check & Agent Commission | N1: 700 | O1: 1000 | P1: 1500 | Q1: 2000 | R1: 3000 | S1: 3500 | T1: 4000 | U1: 5000 | V1: 6000 | W1: 8000 | X1: 9500 | Y1: 10000 | Z1: 12000 | AA1: 15000 | AB1: 20000 | AC1: 30000 | AD1: 40000 | AE1: 50000
A2: Settings pulled from SETTINGS sheet | Min Margin: =SETTINGS!B5% Warning: =SETTINGS!B6% Commission: =SETTINGS!B7% ← change in SETTINGS tab
A3: Min Approval Margin % | D3: =SETTINGS!B5&"%" -> 15% | E3: Warning Margin % | H3: =SETTINGS!B6&"%" -> 20% | I3: Agent Commission % | L3: =SETTINGS!B7&"% of Margin" -> 10% of Margin
A5: ORDER # | B5: DATE | C5: CUSTOMER | D5: AGENT NAME | E5: PRODUCT CODE | F5: ORDER QTY | G5: SALE PRICE/UNIT (₹) | H5: COST/UNIT (₹) | I5: MARGIN ₹/UNIT | J5: MARGIN % | K5: STATUS | L5: AGENT COMMISSION (₹)
A6: ORD-0001 | H6: =IF(OR(E6="",F6=""),"",IFERROR(INDEX('COST TABLE'!$C$4:$T$200,MATCH(E6,'COST TABLE'!$A$4:$A$200,0),MATCH(LARGE(IF(N1:AE1<=F6,N1:AE1),1),N1:AE1,0)),"⚠ NOT FOUND")) | I6: =IF(OR(G6="",H6=""),"",G6-H6) | J6: =IF(OR(G6="",H6=""),"",IF(G6=0,0,(G6-H6)/G6)) | K6: =IF(OR(G6="",H6=""),"",IF(H6="⚠ NOT FOUND","⚠ CHECK PRODUCT",IF((G6-H6)/G6<SETTINGS!$B$5/100,"❌ DISAPPROVED",IF((G6-H6)/G6<SETTINGS!$B$6/100,"⚠ LOW MARGIN","✅ APPROVED")))) | L6: =IF(OR(I6="",I6<=0),"",I6*F6*SETTINGS!$B$7/100)
A7: ORD-0002 | H7: =IF(OR(E7="",F7=""),"",IFERROR(INDEX('COST TABLE'!$C$4:$T$200,MATCH(E7,'COST TABLE'!$A$4:$A$200,0),MATCH(LARGE(IF(N1:AE1<=F7,N1:AE1),1),N1:AE1,0)),"⚠ NOT FOUND")) | I7: =IF(OR(G7="",H7=""),"",G7-H7) | J7: =IF(OR(G7="",H7=""),"",IF(G7=0,0,(G7-H7)/G7)) | K7: =IF(OR(G7="",H7=""),"",IF(H7="⚠ NOT FOUND","⚠ CHECK PRODUCT",IF((G7-H7)/G7<SETTINGS!$B$5/100,"❌ DISAPPROVED",IF((G7-H7)/G7<SETTINGS!$B$6/100,"⚠ LOW MARGIN","✅ APPROVED")))) | L7: =IF(OR(I7="",I7<=0),"",I7*F7*SETTINGS!$B$7/100)
A8: ORD-0003 | H8: =IF(OR(E8="",F8=""),"",IFERROR(INDEX('COST TABLE'!$C$4:$T$200,MATCH(E8,'COST TABLE'!$A$4:$A$200,0),MATCH(LARGE(IF(N1:AE1<=F8,N1:AE1),1),N1:AE1,0)),"⚠ NOT FOUND")) | I8: =IF(OR(G8="",H8=""),"",G8-H8) | J8: =IF(OR(G8="",H8=""),"",IF(G8=0,0,(G8-H8)/G8)) | K8: =IF(OR(G8="",H8=""),"",IF(H8="⚠ NOT FOUND","⚠ CHECK PRODUCT",IF((G8-H8)/G8<SETTINGS!$B$5/100,"❌ DISAPPROVED",IF((G8-H8)/G8<SETTINGS!$B$6/100,"⚠ LOW MARGIN","✅ APPROVED")))) | L8: =IF(OR(I8="",I8<=0),"",I8*F8*SETTINGS!$B$7/100)
A9: ORD-0004 | H9: =IF(OR(E9="",F9=""),"",IFERROR(INDEX('COST TABLE'!$C$4:$T$200,MATCH(E9,'COST TABLE'!$A$4:$A$200,0),MATCH(LARGE(IF(N1:AE1<=F9,N1:AE1),1),N1:AE1,0)),"⚠ NOT FOUND")) | I9: =IF(OR(G9="",H9=""),"",G9-H9) | J9: =IF(OR(G9="",H9=""),"",IF(G9=0,0,(G9-H9)/G9)) | K9: =IF(OR(G9="",H9=""),"",IF(H9="⚠ NOT FOUND","⚠ CHECK PRODUCT",IF((G9-H9)/G9<SETTINGS!$B$5/100,"❌ DISAPPROVED",IF((G9-H9)/G9<SETTINGS!$B$6/100,"⚠ LOW MARGIN","✅ APPROVED")))) | L9: =IF(OR(I9="",I9<=0),"",I9*F9*SETTINGS!$B$7/100)
A10: ORD-0005 | H10: =IF(OR(E10="",F10=""),"",IFERROR(INDEX('COST TABLE'!$C$4:$T$200,MATCH(E10,'COST TABLE'!$A$4:$A$200,0),MATCH(LARGE(IF(N1:AE1<=F10,N1:AE1),1),N1:AE1,0)),"⚠ NOT FOUND")) | I10: =IF(OR(G10="",H10=""),"",G10-H10) | J10: =IF(OR(G10="",H10=""),"",IF(G10=0,0,(G10-H10)/G10)) | K10: =IF(OR(G10="",H10=""),"",IF(H10="⚠ NOT FOUND","⚠ CHECK PRODUCT",IF((G10-H10)/G10<SETTINGS!$B$5/100,"❌ DISAPPROVED",IF((G10-H10)/G10<SETTINGS!$B$6/100,"⚠ LOW MARGIN","✅ APPROVED")))) | L10: =IF(OR(I10="",I10<=0),"",I10*F10*SETTINGS!$B$7/100)
A11: ORD-0006 | H11: =IF(OR(E11="",F11=""),"",IFERROR(INDEX('COST TABLE'!$C$4:$T$200,MATCH(E11,'COST TABLE'!$A$4:$A$200,0),MATCH(LARGE(IF(N1:AE1<=F11,N1:AE1),1),N1:AE1,0)),"⚠ NOT FOUND")) | I11: =IF(OR(G11="",H11=""),"",G11-H11) | J11: =IF(OR(G11="",H11=""),"",IF(G11=0,0,(G11-H11)/G11)) | K11: =IF(OR(G11="",H11=""),"",IF(H11="⚠ NOT FOUND","⚠ CHECK PRODUCT",IF((G11-H11)/G11<SETTINGS!$B$5/100,"❌ DISAPPROVED",IF((G11-H11)/G11<SETTINGS!$B$6/100,"⚠ LOW MARGIN","✅ APPROVED")))) | L11: =IF(OR(I11="",I11<=0),"",I11*F11*SETTINGS!$B$7/100)
A12: ORD-0007 | H12: =IF(OR(E12="",F12=""),"",IFERROR(INDEX('COST TABLE'!$C$4:$T$200,MATCH(E12,'COST TABLE'!$A$4:$A$200,0),MATCH(LARGE(IF(N1:AE1<=F12,N1:AE1),1),N1:AE1,0)),"⚠ NOT FOUND")) | I12: =IF(OR(G12="",H12=""),"",G12-H12) | J12: =IF(OR(G12="",H12=""),"",IF(G12=0,0,(G12-H12)/G12)) | K12: =IF(OR(G12="",H12=""),"",IF(H12="⚠ NOT FOUND","⚠ CHECK PRODUCT",IF((G12-H12)/G12<SETTINGS!$B$5/100,"❌ DISAPPROVED",IF((G12-H12)/G12<SETTINGS!$B$6/100,"⚠ LOW MARGIN","✅ APPROVED")))) | L12: =IF(OR(I12="",I12<=0),"",I12*F12*SETTINGS!$B$7/100)
A13: ORD-0008 | H13: =IF(OR(E13="",F13=""),"",IFERROR(INDEX('COST TABLE'!$C$4:$T$200,MATCH(E13,'COST TABLE'!$A$4:$A$200,0),MATCH(LARGE(IF(N1:AE1<=F13,N1:AE1),1),N1:AE1,0)),"⚠ NOT FOUND")) | I13: =IF(OR(G13="",H13=""),"",G13-H13) | J13: =IF(OR(G13="",H13=""),"",IF(G13=0,0,(G13-H13)/G13)) | K13: =IF(OR(G13="",H13=""),"",IF(H13="⚠ NOT FOUND","⚠ CHECK PRODUCT",IF((G13-H13)/G13<SETTINGS!$B$5/100,"❌ DISAPPROVED",IF((G13-H13)/G13<SETTINGS!$B$6/100,"⚠ LOW MARGIN","✅ APPROVED")))) | L13: =IF(OR(I13="",I13<=0),"",I13*F13*SETTINGS!$B$7/100)
A14: ORD-0009 | H14: =IF(OR(E14="",F14=""),"",IFERROR(INDEX('COST TABLE'!$C$4:$T$200,MATCH(E14,'COST TABLE'!$A$4:$A$200,0),MATCH(LARGE(IF(N1:AE1<=F14,N1:AE1),1),N1:AE1,0)),"⚠ NOT FOUND")) | I14: =IF(OR(G14="",H14=""),"",G14-H14) | J14: =IF(OR(G14="",H14=""),"",IF(G14=0,0,(G14-H14)/G14)) | K14: =IF(OR(G14="",H14=""),"",IF(H14="⚠ NOT FOUND","⚠ CHECK PRODUCT",IF((G14-H14)/G14<SETTINGS!$B$5/100,"❌ DISAPPROVED",IF((G14-H14)/G14<SETTINGS!$B$6/100,"⚠ LOW MARGIN","✅ APPROVED")))) | L14: =IF(OR(I14="",I14<=0),"",I14*F14*SETTINGS!$B$7/100)
A15: ORD-0010 | H15: =IF(OR(E15="",F15=""),"",IFERROR(INDEX('COST TABLE'!$C$4:$T$200,MATCH(E15,'COST TABLE'!$A$4:$A$200,0),MATCH(LARGE(IF(N1:AE1<=F15,N1:AE1),1),N1:AE1,0)),"⚠ NOT FOUND")) | I15: =IF(OR(G15="",H15=""),"",G15-H15) | J15: =IF(OR(G15="",H15=""),"",IF(G15=0,0,(G15-H15)/G15)) | K15: =IF(OR(G15="",H15=""),"",IF(H15="⚠ NOT FOUND","⚠ CHECK PRODUCT",IF((G15-H15)/G15<SETTINGS!$B$5/100,"❌ DISAPPROVED",IF((G15-H15)/G15<SETTINGS!$B$6/100,"⚠ LOW MARGIN","✅ APPROVED")))) | L15: =IF(OR(I15="",I15<=0),"",I15*F15*SETTINGS!$B$7/100)
A16: ORD-0011 | H16: =IF(OR(E16="",F16=""),"",IFERROR(INDEX('COST TABLE'!$C$4:$T$200,MATCH(E16,'COST TABLE'!$A$4:$A$200,0),MATCH(LARGE(IF(N1:AE1<=F16,N1:AE1),1),N1:AE1,0)),"⚠ NOT FOUND")) | I16: =IF(OR(G16="",H16=""),"",G16-H16) | J16: =IF(OR(G16="",H16=""),"",IF(G16=0,0,(G16-H16)/G16)) | K16: =IF(OR(G16="",H16=""),"",IF(H16="⚠ NOT FOUND","⚠ CHECK PRODUCT",IF((G16-H16)/G16<SETTINGS!$B$5/100,"❌ DISAPPROVED",IF((G16-H16)/G16<SETTINGS!$B$6/100,"⚠ LOW MARGIN","✅ APPROVED")))) | L16: =IF(OR(I16="",I16<=0),"",I16*F16*SETTINGS!$B$7/100)
A17: ORD-0012 | H17: =IF(OR(E17="",F17=""),"",IFERROR(INDEX('COST TABLE'!$C$4:$T$200,MATCH(E17,'COST TABLE'!$A$4:$A$200,0),MATCH(LARGE(IF(N1:AE1<=F17,N1:AE1),1),N1:AE1,0)),"⚠ NOT FOUND")) | I17: =IF(OR(G17="",H17=""),"",G17-H17) | J17: =IF(OR(G17="",H17=""),"",IF(G17=0,0,(G17-H17)/G17)) | K17: =IF(OR(G17="",H17=""),"",IF(H17="⚠ NOT FOUND","⚠ CHECK PRODUCT",IF((G17-H17)/G17<SETTINGS!$B$5/100,"❌ DISAPPROVED",IF((G17-H17)/G17<SETTINGS!$B$6/100,"⚠ LOW MARGIN","✅ APPROVED")))) | L17: =IF(OR(I17="",I17<=0),"",I17*F17*SETTINGS!$B$7/100)
A18: ORD-0013 | H18: =IF(OR(E18="",F18=""),"",IFERROR(INDEX('COST TABLE'!$C$4:$T$200,MATCH(E18,'COST TABLE'!$A$4:$A$200,0),MATCH(LARGE(IF(N1:AE1<=F18,N1:AE1),1),N1:AE1,0)),"⚠ NOT FOUND")) | I18: =IF(OR(G18="",H18=""),"",G18-H18) | J18: =IF(OR(G18="",H18=""),"",IF(G18=0,0,(G18-H18)/G18)) | K18: =IF(OR(G18="",H18=""),"",IF(H18="⚠ NOT FOUND","⚠ CHECK PRODUCT",IF((G18-H18)/G18<SETTINGS!$B$5/100,"❌ DISAPPROVED",IF((G18-H18)/G18<SETTINGS!$B$6/100,"⚠ LOW MARGIN","✅ APPROVED")))) | L18: =IF(OR(I18="",I18<=0),"",I18*F18*SETTINGS!$B$7/100)
A19: ORD-0014 | H19: =IF(OR(E19="",F19=""),"",IFERROR(INDEX('COST TABLE'!$C$4:$T$200,MATCH(E19,'COST TABLE'!$A$4:$A$200,0),MATCH(LARGE(IF(N1:AE1<=F19,N1:AE1),1),N1:AE1,0)),"⚠ NOT FOUND")) | I19: =IF(OR(G19="",H19=""),"",G19-H19) | J19: =IF(OR(G19="",H19=""),"",IF(G19=0,0,(G19-H19)/G19)) | K19: =IF(OR(G19="",H19=""),"",IF(H19="⚠ NOT FOUND","⚠ CHECK PRODUCT",IF((G19-H19)/G19<SETTINGS!$B$5/100,"❌ DISAPPROVED",IF((G19-H19)/G19<SETTINGS!$B$6/100,"⚠ LOW MARGIN","✅ APPROVED")))) | L19: =IF(OR(I19="",I19<=0),"",I19*F19*SETTINGS!$B$7/100)
A20: ORD-0015 | H20: =IF(OR(E20="",F20=""),"",IFERROR(INDEX('COST TABLE'!$C$4:$T$200,MATCH(E20,'COST TABLE'!$A$4:$A$200,0),MATCH(LARGE(IF(N1:AE1<=F20,N1:AE1),1),N1:AE1,0)),"⚠ NOT FOUND")) | I20: =IF(OR(G20="",H20=""),"",G20-H20) | J20: =IF(OR(G20="",H20=""),"",IF(G20=0,0,(G20-H20)/G20)) | K20: =IF(OR(G20="",H20=""),"",IF(H20="⚠ NOT FOUND","⚠ CHECK PRODUCT",IF((G20-H20)/G20<SETTINGS!$B$5/100,"❌ DISAPPROVED",IF((G20-H20)/G20<SETTINGS!$B$6/100,"⚠ LOW MARGIN","✅ APPROVED")))) | L20: =IF(OR(I20="",I20<=0),"",I20*F20*SETTINGS!$B$7/100)
A21: ORD-0016 | H21: =IF(OR(E21="",F21=""),"",IFERROR(INDEX('COST TABLE'!$C$4:$T$200,MATCH(E21,'COST TABLE'!$A$4:$A$200,0),MATCH(LARGE(IF(N1:AE1<=F21,N1:AE1),1),N1:AE1,0)),"⚠ NOT FOUND")) | I21: =IF(OR(G21="",H21=""),"",G21-H21) | J21: =IF(OR(G21="",H21=""),"",IF(G21=0,0,(G21-H21)/G21)) | K21: =IF(OR(G21="",H21=""),"",IF(H21="⚠ NOT FOUND","⚠ CHECK PRODUCT",IF((G21-H21)/G21<SETTINGS!$B$5/100,"❌ DISAPPROVED",IF((G21-H21)/G21<SETTINGS!$B$6/100,"⚠ LOW MARGIN","✅ APPROVED")))) | L21: =IF(OR(I21="",I21<=0),"",I21*F21*SETTINGS!$B$7/100)
A22: ORD-0017 | H22: =IF(OR(E22="",F22=""),"",IFERROR(INDEX('COST TABLE'!$C$4:$T$200,MATCH(E22,'COST TABLE'!$A$4:$A$200,0),MATCH(LARGE(IF(N1:AE1<=F22,N1:AE1),1),N1:AE1,0)),"⚠ NOT FOUND")) | I22: =IF(OR(G22="",H22=""),"",G22-H22) | J22: =IF(OR(G22="",H22=""),"",IF(G22=0,0,(G22-H22)/G22)) | K22: =IF(OR(G22="",H22=""),"",IF(H22="⚠ NOT FOUND","⚠ CHECK PRODUCT",IF((G22-H22)/G22<SETTINGS!$B$5/100,"❌ DISAPPROVED",IF((G22-H22)/G22<SETTINGS!$B$6/100,"⚠ LOW MARGIN","✅ APPROVED")))) | L22: =IF(OR(I22="",I22<=0),"",I22*F22*SETTINGS!$B$7/100)
A23: ORD-0018 | H23: =IF(OR(E23="",F23=""),"",IFERROR(INDEX('COST TABLE'!$C$4:$T$200,MATCH(E23,'COST TABLE'!$A$4:$A$200,0),MATCH(LARGE(IF(N1:AE1<=F23,N1:AE1),1),N1:AE1,0)),"⚠ NOT FOUND")) | I23: =IF(OR(G23="",H23=""),"",G23-H23) | J23: =IF(OR(G23="",H23=""),"",IF(G23=0,0,(G23-H23)/G23)) | K23: =IF(OR(G23="",H23=""),"",IF(H23="⚠ NOT FOUND","⚠ CHECK PRODUCT",IF((G23-H23)/G23<SETTINGS!$B$5/100,"❌ DISAPPROVED",IF((G23-H23)/G23<SETTINGS!$B$6/100,"⚠ LOW MARGIN","✅ APPROVED")))) | L23: =IF(OR(I23="",I23<=0),"",I23*F23*SETTINGS!$B$7/100)
A24: ORD-0019 | H24: =IF(OR(E24="",F24=""),"",IFERROR(INDEX('COST TABLE'!$C$4:$T$200,MATCH(E24,'COST TABLE'!$A$4:$A$200,0),MATCH(LARGE(IF(N1:AE1<=F24,N1:AE1),1),N1:AE1,0)),"⚠ NOT FOUND")) | I24: =IF(OR(G24="",H24=""),"",G24-H24) | J24: =IF(OR(G24="",H24=""),"",IF(G24=0,0,(G24-H24)/G24)) | K24: =IF(OR(G24="",H24=""),"",IF(H24="⚠ NOT FOUND","⚠ CHECK PRODUCT",IF((G24-H24)/G24<SETTINGS!$B$5/100,"❌ DISAPPROVED",IF((G24-H24)/G24<SETTINGS!$B$6/100,"⚠ LOW MARGIN","✅ APPROVED")))) | L24: =IF(OR(I24="",I24<=0),"",I24*F24*SETTINGS!$B$7/100)
A25: ORD-0020 | H25: =IF(OR(E25="",F25=""),"",IFERROR(INDEX('COST TABLE'!$C$4:$T$200,MATCH(E25,'COST TABLE'!$A$4:$A$200,0),MATCH(LARGE(IF(N1:AE1<=F25,N1:AE1),1),N1:AE1,0)),"⚠ NOT FOUND")) | I25: =IF(OR(G25="",H25=""),"",G25-H25) | J25: =IF(OR(G25="",H25=""),"",IF(G25=0,0,(G25-H25)/G25)) | K25: =IF(OR(G25="",H25=""),"",IF(H25="⚠ NOT FOUND","⚠ CHECK PRODUCT",IF((G25-H25)/G25<SETTINGS!$B$5/100,"❌ DISAPPROVED",IF((G25-H25)/G25<SETTINGS!$B$6/100,"⚠ LOW MARGIN","✅ APPROVED")))) | L25: =IF(OR(I25="",I25<=0),"",I25*F25*SETTINGS!$B$7/100)
A26: ORD-0021 | H26: =IF(OR(E26="",F26=""),"",IFERROR(INDEX('COST TABLE'!$C$4:$T$200,MATCH(E26,'COST TABLE'!$A$4:$A$200,0),MATCH(LARGE(IF(N1:AE1<=F26,N1:AE1),1),N1:AE1,0)),"⚠ NOT FOUND")) | I26: =IF(OR(G26="",H26=""),"",G26-H26) | J26: =IF(OR(G26="",H26=""),"",IF(G26=0,0,(G26-H26)/G26)) | K26: =IF(OR(G26="",H26=""),"",IF(H26="⚠ NOT FOUND","⚠ CHECK PRODUCT",IF((G26-H26)/G26<SETTINGS!$B$5/100,"❌ DISAPPROVED",IF((G26-H26)/G26<SETTINGS!$B$6/100,"⚠ LOW MARGIN","✅ APPROVED")))) | L26: =IF(OR(I26="",I26<=0),"",I26*F26*SETTINGS!$B$7/100)
A27: ORD-0022 | H27: =IF(OR(E27="",F27=""),"",IFERROR(INDEX('COST TABLE'!$C$4:$T$200,MATCH(E27,'COST TABLE'!$A$4:$A$200,0),MATCH(LARGE(IF(N1:AE1<=F27,N1:AE1),1),N1:AE1,0)),"⚠ NOT FOUND")) | I27: =IF(OR(G27="",H27=""),"",G27-H27) | J27: =IF(OR(G27="",H27=""),"",IF(G27=0,0,(G27-H27)/G27)) | K27: =IF(OR(G27="",H27=""),"",IF(H27="⚠ NOT FOUND","⚠ CHECK PRODUCT",IF((G27-H27)/G27<SETTINGS!$B$5/100,"❌ DISAPPROVED",IF((G27-H27)/G27<SETTINGS!$B$6/100,"⚠ LOW MARGIN","✅ APPROVED")))) | L27: =IF(OR(I27="",I27<=0),"",I27*F27*SETTINGS!$B$7/100)
A28: ORD-0023 | H28: =IF(OR(E28="",F28=""),"",IFERROR(INDEX('COST TABLE'!$C$4:$T$200,MATCH(E28,'COST TABLE'!$A$4:$A$200,0),MATCH(LARGE(IF(N1:AE1<=F28,N1:AE1),1),N1:AE1,0)),"⚠ NOT FOUND")) | I28: =IF(OR(G28="",H28=""),"",G28-H28) | J28: =IF(OR(G28="",H28=""),"",IF(G28=0,0,(G28-H28)/G28)) | K28: =IF(OR(G28="",H28=""),"",IF(H28="⚠ NOT FOUND","⚠ CHECK PRODUCT",IF((G28-H28)/G28<SETTINGS!$B$5/100,"❌ DISAPPROVED",IF((G28-H28)/G28<SETTINGS!$B$6/100,"⚠ LOW MARGIN","✅ APPROVED")))) | L28: =IF(OR(I28="",I28<=0),"",I28*F28*SETTINGS!$B$7/100)
A29: ORD-0024 | H29: =IF(OR(E29="",F29=""),"",IFERROR(INDEX('COST TABLE'!$C$4:$T$200,MATCH(E29,'COST TABLE'!$A$4:$A$200,0),MATCH(LARGE(IF(N1:AE1<=F29,N1:AE1),1),N1:AE1,0)),"⚠ NOT FOUND")) | I29: =IF(OR(G29="",H29=""),"",G29-H29) | J29: =IF(OR(G29="",H29=""),"",IF(G29=0,0,(G29-H29)/G29)) | K29: =IF(OR(G29="",H29=""),"",IF(H29="⚠ NOT FOUND","⚠ CHECK PRODUCT",IF((G29-H29)/G29<SETTINGS!$B$5/100,"❌ DISAPPROVED",IF((G29-H29)/G29<SETTINGS!$B$6/100,"⚠ LOW MARGIN","✅ APPROVED")))) | L29: =IF(OR(I29="",I29<=0),"",I29*F29*SETTINGS!$B$7/100)
A30: ORD-0025 | H30: =IF(OR(E30="",F30=""),"",IFERROR(INDEX('COST TABLE'!$C$4:$T$200,MATCH(E30,'COST TABLE'!$A$4:$A$200,0),MATCH(LARGE(IF(N1:AE1<=F30,N1:AE1),1),N1:AE1,0)),"⚠ NOT FOUND")) | I30: =IF(OR(G30="",H30=""),"",G30-H30) | J30: =IF(OR(G30="",H30=""),"",IF(G30=0,0,(G30-H30)/G30)) | K30: =IF(OR(G30="",H30=""),"",IF(H30="⚠ NOT FOUND","⚠ CHECK PRODUCT",IF((G30-H30)/G30<SETTINGS!$B$5/100,"❌ DISAPPROVED",IF((G30-H30)/G30<SETTINGS!$B$6/100,"⚠ LOW MARGIN","✅ APPROVED")))) | L30: =IF(OR(I30="",I30<=0),"",I30*F30*SETTINGS!$B$7/100)
A31: ORD-0026 | H31: =IF(OR(E31="",F31=""),"",IFERROR(INDEX('COST TABLE'!$C$4:$T$200,MATCH(E31,'COST TABLE'!$A$4:$A$200,0),MATCH(LARGE(IF(N1:AE1<=F31,N1:AE1),1),N1:AE1,0)),"⚠ NOT FOUND")) | I31: =IF(OR(G31="",H31=""),"",G31-H31) | J31: =IF(OR(G31="",H31=""),"",IF(G31=0,0,(G31-H31)/G31)) | K31: =IF(OR(G31="",H31=""),"",IF(H31="⚠ NOT FOUND","⚠ CHECK PRODUCT",IF((G31-H31)/G31<SETTINGS!$B$5/100,"❌ DISAPPROVED",IF((G31-H31)/G31<SETTINGS!$B$6/100,"⚠ LOW MARGIN","✅ APPROVED")))) | L31: =IF(OR(I31="",I31<=0),"",I31*F31*SETTINGS!$B$7/100)
A32: ORD-0027 | H32: =IF(OR(E32="",F32=""),"",IFERROR(INDEX('COST TABLE'!$C$4:$T$200,MATCH(E32,'COST TABLE'!$A$4:$A$200,0),MATCH(LARGE(IF(N1:AE1<=F32,N1:AE1),1),N1:AE1,0)),"⚠ NOT FOUND")) | I32: =IF(OR(G32="",H32=""),"",G32-H32) | J32: =IF(OR(G32="",H32=""),"",IF(G32=0,0,(G32-H32)/G32)) | K32: =IF(OR(G32="",H32=""),"",IF(H32="⚠ NOT FOUND","⚠ CHECK PRODUCT",IF((G32-H32)/G32<SETTINGS!$B$5/100,"❌ DISAPPROVED",IF((G32-H32)/G32<SETTINGS!$B$6/100,"⚠ LOW MARGIN","✅ APPROVED")))) | L32: =IF(OR(I32="",I32<=0),"",I32*F32*SETTINGS!$B$7/100)
A33: ORD-0028 | H33: =IF(OR(E33="",F33=""),"",IFERROR(INDEX('COST TABLE'!$C$4:$T$200,MATCH(E33,'COST TABLE'!$A$4:$A$200,0),MATCH(LARGE(IF(N1:AE1<=F33,N1:AE1),1),N1:AE1,0)),"⚠ NOT FOUND")) | I33: =IF(OR(G33="",H33=""),"",G33-H33) | J33: =IF(OR(G33="",H33=""),"",IF(G33=0,0,(G33-H33)/G33)) | K33: =IF(OR(G33="",H33=""),"",IF(H33="⚠ NOT FOUND","⚠ CHECK PRODUCT",IF((G33-H33)/G33<SETTINGS!$B$5/100,"❌ DISAPPROVED",IF((G33-H33)/G33<SETTINGS!$B$6/100,"⚠ LOW MARGIN","✅ APPROVED")))) | L33: =IF(OR(I33="",I33<=0),"",I33*F33*SETTINGS!$B$7/100)
A34: ORD-0029 | H34: =IF(OR(E34="",F34=""),"",IFERROR(INDEX('COST TABLE'!$C$4:$T$200,MATCH(E34,'COST TABLE'!$A$4:$A$200,0),MATCH(LARGE(IF(N1:AE1<=F34,N1:AE1),1),N1:AE1,0)),"⚠ NOT FOUND")) | I34: =IF(OR(G34="",H34=""),"",G34-H34) | J34: =IF(OR(G34="",H34=""),"",IF(G34=0,0,(G34-H34)/G34)) | K34: =IF(OR(G34="",H34=""),"",IF(H34="⚠ NOT FOUND","⚠ CHECK PRODUCT",IF((G34-H34)/G34<SETTINGS!$B$5/100,"❌ DISAPPROVED",IF((G34-H34)/G34<SETTINGS!$B$6/100,"⚠ LOW MARGIN","✅ APPROVED")))) | L34: =IF(OR(I34="",I34<=0),"",I34*F34*SETTINGS!$B$7/100)
A35: ORD-0030 | H35: =IF(OR(E35="",F35=""),"",IFERROR(INDEX('COST TABLE'!$C$4:$T$200,MATCH(E35,'COST TABLE'!$A$4:$A$200,0),MATCH(LARGE(IF(N1:AE1<=F35,N1:AE1),1),N1:AE1,0)),"⚠ NOT FOUND")) | I35: =IF(OR(G35="",H35=""),"",G35-H35) | J35: =IF(OR(G35="",H35=""),"",IF(G35=0,0,(G35-H35)/G35)) | K35: =IF(OR(G35="",H35=""),"",IF(H35="⚠ NOT FOUND","⚠ CHECK PRODUCT",IF((G35-H35)/G35<SETTINGS!$B$5/100,"❌ DISAPPROVED",IF((G35-H35)/G35<SETTINGS!$B$6/100,"⚠ LOW MARGIN","✅ APPROVED")))) | L35: =IF(OR(I35="",I35<=0),"",I35*F35*SETTINGS!$B$7/100)
A36: ORD-0031 | H36: =IF(OR(E36="",F36=""),"",IFERROR(INDEX('COST TABLE'!$C$4:$T$200,MATCH(E36,'COST TABLE'!$A$4:$A$200,0),MATCH(LARGE(IF(N1:AE1<=F36,N1:AE1),1),N1:AE1,0)),"⚠ NOT FOUND")) | I36: =IF(OR(G36="",H36=""),"",G36-H36) | J36: =IF(OR(G36="",H36=""),"",IF(G36=0,0,(G36-H36)/G36)) | K36: =IF(OR(G36="",H36=""),"",IF(H36="⚠ NOT FOUND","⚠ CHECK PRODUCT",IF((G36-H36)/G36<SETTINGS!$B$5/100,"❌ DISAPPROVED",IF((G36-H36)/G36<SETTINGS!$B$6/100,"⚠ LOW MARGIN","✅ APPROVED")))) | L36: =IF(OR(I36="",I36<=0),"",I36*F36*SETTINGS!$B$7/100)
A37: ORD-0032 | H37: =IF(OR(E37="",F37=""),"",IFERROR(INDEX('COST TABLE'!$C$4:$T$200,MATCH(E37,'COST TABLE'!$A$4:$A$200,0),MATCH(LARGE(IF(N1:AE1<=F37,N1:AE1),1),N1:AE1,0)),"⚠ NOT FOUND")) | I37: =IF(OR(G37="",H37=""),"",G37-H37) | J37: =IF(OR(G37="",H37=""),"",IF(G37=0,0,(G37-H37)/G37)) | K37: =IF(OR(G37="",H37=""),"",IF(H37="⚠ NOT FOUND","⚠ CHECK PRODUCT",IF((G37-H37)/G37<SETTINGS!$B$5/100,"❌ DISAPPROVED",IF((G37-H37)/G37<SETTINGS!$B$6/100,"⚠ LOW MARGIN","✅ APPROVED")))) | L37: =IF(OR(I37="",I37<=0),"",I37*F37*SETTINGS!$B$7/100)
A38: ORD-0033 | H38: =IF(OR(E38="",F38=""),"",IFERROR(INDEX('COST TABLE'!$C$4:$T$200,MATCH(E38,'COST TABLE'!$A$4:$A$200,0),MATCH(LARGE(IF(N1:AE1<=F38,N1:AE1),1),N1:AE1,0)),"⚠ NOT FOUND")) | I38: =IF(OR(G38="",H38=""),"",G38-H38) | J38: =IF(OR(G38="",H38=""),"",IF(G38=0,0,(G38-H38)/G38)) | K38: =IF(OR(G38="",H38=""),"",IF(H38="⚠ NOT FOUND","⚠ CHECK PRODUCT",IF((G38-H38)/G38<SETTINGS!$B$5/100,"❌ DISAPPROVED",IF((G38-H38)/G38<SETTINGS!$B$6/100,"⚠ LOW MARGIN","✅ APPROVED")))) | L38: =IF(OR(I38="",I38<=0),"",I38*F38*SETTINGS!$B$7/100)
A39: ORD-0034 | H39: =IF(OR(E39="",F39=""),"",IFERROR(INDEX('COST TABLE'!$C$4:$T$200,MATCH(E39,'COST TABLE'!$A$4:$A$200,0),MATCH(LARGE(IF(N1:AE1<=F39,N1:AE1),1),N1:AE1,0)),"⚠ NOT FOUND")) | I39: =IF(OR(G39="",H39=""),"",G39-H39) | J39: =IF(OR(G39="",H39=""),"",IF(G39=0,0,(G39-H39)/G39)) | K39: =IF(OR(G39="",H39=""),"",IF(H39="⚠ NOT FOUND","⚠ CHECK PRODUCT",IF((G39-H39)/G39<SETTINGS!$B$5/100,"❌ DISAPPROVED",IF((G39-H39)/G39<SETTINGS!$B$6/100,"⚠ LOW MARGIN","✅ APPROVED")))) | L39: =IF(OR(I39="",I39<=0),"",I39*F39*SETTINGS!$B$7/100)
A40: ORD-0035 | H40: =IF(OR(E40="",F40=""),"",IFERROR(INDEX('COST TABLE'!$C$4:$T$200,MATCH(E40,'COST TABLE'!$A$4:$A$200,0),MATCH(LARGE(IF(N1:AE1<=F40,N1:AE1),1),N1:AE1,0)),"⚠ NOT FOUND")) | I40: =IF(OR(G40="",H40=""),"",G40-H40) | J40: =IF(OR(G40="",H40=""),"",IF(G40=0,0,(G40-H40)/G40)) | K40: =IF(OR(G40="",H40=""),"",IF(H40="⚠ NOT FOUND","⚠ CHECK PRODUCT",IF((G40-H40)/G40<SETTINGS!$B$5/100,"❌ DISAPPROVED",IF((G40-H40)/G40<SETTINGS!$B$6/100,"⚠ LOW MARGIN","✅ APPROVED")))) | L40: =IF(OR(I40="",I40<=0),"",I40*F40*SETTINGS!$B$7/100)
A41: ORD-0036 | H41: =IF(OR(E41="",F41=""),"",IFERROR(INDEX('COST TABLE'!$C$4:$T$200,MATCH(E41,'COST TABLE'!$A$4:$A$200,0),MATCH(LARGE(IF(N1:AE1<=F41,N1:AE1),1),N1:AE1,0)),"⚠ NOT FOUND")) | I41: =IF(OR(G41="",H41=""),"",G41-H41) | J41: =IF(OR(G41="",H41=""),"",IF(G41=0,0,(G41-H41)/G41)) | K41: =IF(OR(G41="",H41=""),"",IF(H41="⚠ NOT FOUND","⚠ CHECK PRODUCT",IF((G41-H41)/G41<SETTINGS!$B$5/100,"❌ DISAPPROVED",IF((G41-H41)/G41<SETTINGS!$B$6/100,"⚠ LOW MARGIN","✅ APPROVED")))) | L41: =IF(OR(I41="",I41<=0),"",I41*F41*SETTINGS!$B$7/100)
...

Sheet AGENT SUMMARY
A1: SALES AGENT COMMISSION SUMMARY
A2: Auto-summarises commissions from ORDER ENTRY sheet. Commissions only counted for ✅ APPROVED orders.
A4: AGENT NAME | B4: TOTAL ORDERS | C4: APPROVED ORDERS | D4: TOTAL SALE VALUE (₹) | E4: TOTAL MARGIN (₹) | F4: TOTAL COMMISSION (₹)
B5: =COUNTIF('ORDER ENTRY'!$D$6:$D$55,$A5) -> 0 | C5: =COUNTIFS('ORDER ENTRY'!$D$6:$D$55,$A5,'ORDER ENTRY'!$K$6:$K$55,"✅ APPROVED") -> 0 | D5: =SUMPRODUCT(('ORDER ENTRY'!$D$6:$D$55=$A5)*('ORDER ENTRY'!$K$6:$K$55="✅ APPROVED")*IFERROR(('ORDER ENTRY'!$G$6:$G$55)*1,0)*IFERROR(('ORDER ENTRY'!$F$6:$F$55)*1,0)) -> 0 | E5: =SUMPRODUCT(('ORDER ENTRY'!$D$6:$D$55=$A5)*('ORDER ENTRY'!$K$6:$K$55="✅ APPROVED")*IFERROR(('ORDER ENTRY'!$I$6:$I$55)*1,0)*IFERROR(('ORDER ENTRY'!$F$6:$F$55)*1,0)) -> 0 | F5: =SUMIF('ORDER ENTRY'!$D$6:$D$55,$A5,'ORDER ENTRY'!$L$6:$L$55) -> 0
B6: =COUNTIF('ORDER ENTRY'!$D$6:$D$55,$A6) -> 0 | C6: =COUNTIFS('ORDER ENTRY'!$D$6:$D$55,$A6,'ORDER ENTRY'!$K$6:$K$55,"✅ APPROVED") -> 0 | D6: =SUMPRODUCT(('ORDER ENTRY'!$D$6:$D$55=$A6)*('ORDER ENTRY'!$K$6:$K$55="✅ APPROVED")*IFERROR(('ORDER ENTRY'!$G$6:$G$55)*1,0)*IFERROR(('ORDER ENTRY'!$F$6:$F$55)*1,0)) -> 0 | E6: =SUMPRODUCT(('ORDER ENTRY'!$D$6:$D$55=$A6)*('ORDER ENTRY'!$K$6:$K$55="✅ APPROVED")*IFERROR(('ORDER ENTRY'!$I$6:$I$55)*1,0)*IFERROR(('ORDER ENTRY'!$F$6:$F$55)*1,0)) -> 0 | F6: =SUMIF('ORDER ENTRY'!$D$6:$D$55,$A6,'ORDER ENTRY'!$L$6:$L$55) -> 0
B7: =COUNTIF('ORDER ENTRY'!$D$6:$D$55,$A7) -> 0 | C7: =COUNTIFS('ORDER ENTRY'!$D$6:$D$55,$A7,'ORDER ENTRY'!$K$6:$K$55,"✅ APPROVED") -> 0 | D7: =SUMPRODUCT(('ORDER ENTRY'!$D$6:$D$55=$A7)*('ORDER ENTRY'!$K$6:$K$55="✅ APPROVED")*IFERROR(('ORDER ENTRY'!$G$6:$G$55)*1,0)*IFERROR(('ORDER ENTRY'!$F$6:$F$55)*1,0)) -> 0 | E7: =SUMPRODUCT(('ORDER ENTRY'!$D$6:$D$55=$A7)*('ORDER ENTRY'!$K$6:$K$55="✅ APPROVED")*IFERROR(('ORDER ENTRY'!$I$6:$I$55)*1,0)*IFERROR(('ORDER ENTRY'!$F$6:$F$55)*1,0)) -> 0 | F7: =SUMIF('ORDER ENTRY'!$D$6:$D$55,$A7,'ORDER ENTRY'!$L$6:$L$55) -> 0
B8: =COUNTIF('ORDER ENTRY'!$D$6:$D$55,$A8) -> 0 | C8: =COUNTIFS('ORDER ENTRY'!$D$6:$D$55,$A8,'ORDER ENTRY'!$K$6:$K$55,"✅ APPROVED") -> 0 | D8: =SUMPRODUCT(('ORDER ENTRY'!$D$6:$D$55=$A8)*('ORDER ENTRY'!$K$6:$K$55="✅ APPROVED")*IFERROR(('ORDER ENTRY'!$G$6:$G$55)*1,0)*IFERROR(('ORDER ENTRY'!$F$6:$F$55)*1,0)) -> 0 | E8: =SUMPRODUCT(('ORDER ENTRY'!$D$6:$D$55=$A8)*('ORDER ENTRY'!$K$6:$K$55="✅ APPROVED")*IFERROR(('ORDER ENTRY'!$I$6:$I$55)*1,0)*IFERROR(('ORDER ENTRY'!$F$6:$F$55)*1,0)) -> 0 | F8: =SUMIF('ORDER ENTRY'!$D$6:$D$55,$A8,'ORDER ENTRY'!$L$6:$L$55) -> 0
B9: =COUNTIF('ORDER ENTRY'!$D$6:$D$55,$A9) -> 0 | C9: =COUNTIFS('ORDER ENTRY'!$D$6:$D$55,$A9,'ORDER ENTRY'!$K$6:$K$55,"✅ APPROVED") -> 0 | D9: =SUMPRODUCT(('ORDER ENTRY'!$D$6:$D$55=$A9)*('ORDER ENTRY'!$K$6:$K$55="✅ APPROVED")*IFERROR(('ORDER ENTRY'!$G$6:$G$55)*1,0)*IFERROR(('ORDER ENTRY'!$F$6:$F$55)*1,0)) -> 0 | E9: =SUMPRODUCT(('ORDER ENTRY'!$D$6:$D$55=$A9)*('ORDER ENTRY'!$K$6:$K$55="✅ APPROVED")*IFERROR(('ORDER ENTRY'!$I$6:$I$55)*1,0)*IFERROR(('ORDER ENTRY'!$F$6:$F$55)*1,0)) -> 0 | F9: =SUMIF('ORDER ENTRY'!$D$6:$D$55,$A9,'ORDER ENTRY'!$L$6:$L$55) -> 0
B10: =COUNTIF('ORDER ENTRY'!$D$6:$D$55,$A10) -> 0 | C10: =COUNTIFS('ORDER ENTRY'!$D$6:$D$55,$A10,'ORDER ENTRY'!$K$6:$K$55,"✅ APPROVED") -> 0 | D10: =SUMPRODUCT(('ORDER ENTRY'!$D$6:$D$55=$A10)*('ORDER ENTRY'!$K$6:$K$55="✅ APPROVED")*IFERROR(('ORDER ENTRY'!$G$6:$G$55)*1,0)*IFERROR(('ORDER ENTRY'!$F$6:$F$55)*1,0)) -> 0 | E10: =SUMPRODUCT(('ORDER ENTRY'!$D$6:$D$55=$A10)*('ORDER ENTRY'!$K$6:$K$55="✅ APPROVED")*IFERROR(('ORDER ENTRY'!$I$6:$I$55)*1,0)*IFERROR(('ORDER ENTRY'!$F$6:$F$55)*1,0)) -> 0 | F10: =SUMIF('ORDER ENTRY'!$D$6:$D$55,$A10,'ORDER ENTRY'!$L$6:$L$55) -> 0
B11: =COUNTIF('ORDER ENTRY'!$D$6:$D$55,$A11) -> 0 | C11: =COUNTIFS('ORDER ENTRY'!$D$6:$D$55,$A11,'ORDER ENTRY'!$K$6:$K$55,"✅ APPROVED") -> 0 | D11: =SUMPRODUCT(('ORDER ENTRY'!$D$6:$D$55=$A11)*('ORDER ENTRY'!$K$6:$K$55="✅ APPROVED")*IFERROR(('ORDER ENTRY'!$G$6:$G$55)*1,0)*IFERROR(('ORDER ENTRY'!$F$6:$F$55)*1,0)) -> 0 | E11: =SUMPRODUCT(('ORDER ENTRY'!$D$6:$D$55=$A11)*('ORDER ENTRY'!$K$6:$K$55="✅ APPROVED")*IFERROR(('ORDER ENTRY'!$I$6:$I$55)*1,0)*IFERROR(('ORDER ENTRY'!$F$6:$F$55)*1,0)) -> 0 | F11: =SUMIF('ORDER ENTRY'!$D$6:$D$55,$A11,'ORDER ENTRY'!$L$6:$L$55) -> 0
B12: =COUNTIF('ORDER ENTRY'!$D$6:$D$55,$A12) -> 0 | C12: =COUNTIFS('ORDER ENTRY'!$D$6:$D$55,$A12,'ORDER ENTRY'!$K$6:$K$55,"✅ APPROVED") -> 0 | D12: =SUMPRODUCT(('ORDER ENTRY'!$D$6:$D$55=$A12)*('ORDER ENTRY'!$K$6:$K$55="✅ APPROVED")*IFERROR(('ORDER ENTRY'!$G$6:$G$55)*1,0)*IFERROR(('ORDER ENTRY'!$F$6:$F$55)*1,0)) -> 0 | E12: =SUMPRODUCT(('ORDER ENTRY'!$D$6:$D$55=$A12)*('ORDER ENTRY'!$K$6:$K$55="✅ APPROVED")*IFERROR(('ORDER ENTRY'!$I$6:$I$55)*1,0)*IFERROR(('ORDER ENTRY'!$F$6:$F$55)*1,0)) -> 0 | F12: =SUMIF('ORDER ENTRY'!$D$6:$D$55,$A12,'ORDER ENTRY'!$L$6:$L$55) -> 0
B13: =COUNTIF('ORDER ENTRY'!$D$6:$D$55,$A13) -> 0 | C13: =COUNTIFS('ORDER ENTRY'!$D$6:$D$55,$A13,'ORDER ENTRY'!$K$6:$K$55,"✅ APPROVED") -> 0 | D13: =SUMPRODUCT(('ORDER ENTRY'!$D$6:$D$55=$A13)*('ORDER ENTRY'!$K$6:$K$55="✅ APPROVED")*IFERROR(('ORDER ENTRY'!$G$6:$G$55)*1,0)*IFERROR(('ORDER ENTRY'!$F$6:$F$55)*1,0)) -> 0 | E13: =SUMPRODUCT(('ORDER ENTRY'!$D$6:$D$55=$A13)*('ORDER ENTRY'!$K$6:$K$55="✅ APPROVED")*IFERROR(('ORDER ENTRY'!$I$6:$I$55)*1,0)*IFERROR(('ORDER ENTRY'!$F$6:$F$55)*1,0)) -> 0 | F13: =SUMIF('ORDER ENTRY'!$D$6:$D$55,$A13,'ORDER ENTRY'!$L$6:$L$55) -> 0
B14: =COUNTIF('ORDER ENTRY'!$D$6:$D$55,$A14) -> 0 | C14: =COUNTIFS('ORDER ENTRY'!$D$6:$D$55,$A14,'ORDER ENTRY'!$K$6:$K$55,"✅ APPROVED") -> 0 | D14: =SUMPRODUCT(('ORDER ENTRY'!$D$6:$D$55=$A14)*('ORDER ENTRY'!$K$6:$K$55="✅ APPROVED")*IFERROR(('ORDER ENTRY'!$G$6:$G$55)*1,0)*IFERROR(('ORDER ENTRY'!$F$6:$F$55)*1,0)) -> 0 | E14: =SUMPRODUCT(('ORDER ENTRY'!$D$6:$D$55=$A14)*('ORDER ENTRY'!$K$6:$K$55="✅ APPROVED")*IFERROR(('ORDER ENTRY'!$I$6:$I$55)*1,0)*IFERROR(('ORDER ENTRY'!$F$6:$F$55)*1,0)) -> 0 | F14: =SUMIF('ORDER ENTRY'!$D$6:$D$55,$A14,'ORDER ENTRY'!$L$6:$L$55) -> 0
B15: =COUNTIF('ORDER ENTRY'!$D$6:$D$55,$A15) -> 0 | C15: =COUNTIFS('ORDER ENTRY'!$D$6:$D$55,$A15,'ORDER ENTRY'!$K$6:$K$55,"✅ APPROVED") -> 0 | D15: =SUMPRODUCT(('ORDER ENTRY'!$D$6:$D$55=$A15)*('ORDER ENTRY'!$K$6:$K$55="✅ APPROVED")*IFERROR(('ORDER ENTRY'!$G$6:$G$55)*1,0)*IFERROR(('ORDER ENTRY'!$F$6:$F$55)*1,0)) -> 0 | E15: =SUMPRODUCT(('ORDER ENTRY'!$D$6:$D$55=$A15)*('ORDER ENTRY'!$K$6:$K$55="✅ APPROVED")*IFERROR(('ORDER ENTRY'!$I$6:$I$55)*1,0)*IFERROR(('ORDER ENTRY'!$F$6:$F$55)*1,0)) -> 0 | F15: =SUMIF('ORDER ENTRY'!$D$6:$D$55,$A15,'ORDER ENTRY'!$L$6:$L$55) -> 0
B16: =COUNTIF('ORDER ENTRY'!$D$6:$D$55,$A16) -> 0 | C16: =COUNTIFS('ORDER ENTRY'!$D$6:$D$55,$A16,'ORDER ENTRY'!$K$6:$K$55,"✅ APPROVED") -> 0 | D16: =SUMPRODUCT(('ORDER ENTRY'!$D$6:$D$55=$A16)*('ORDER ENTRY'!$K$6:$K$55="✅ APPROVED")*IFERROR(('ORDER ENTRY'!$G$6:$G$55)*1,0)*IFERROR(('ORDER ENTRY'!$F$6:$F$55)*1,0)) -> 0 | E16: =SUMPRODUCT(('ORDER ENTRY'!$D$6:$D$55=$A16)*('ORDER ENTRY'!$K$6:$K$55="✅ APPROVED")*IFERROR(('ORDER ENTRY'!$I$6:$I$55)*1,0)*IFERROR(('ORDER ENTRY'!$F$6:$F$55)*1,0)) -> 0 | F16: =SUMIF('ORDER ENTRY'!$D$6:$D$55,$A16,'ORDER ENTRY'!$L$6:$L$55) -> 0
... B19: =COUNTIF('ORDER ENTRY'!$D$6:$D$55,$A19) -> 0 | C19: =COUNTIFS('ORDER ENTRY'!$D$6:$D$55,$A19,'ORDER ENTRY'!$K$6:$K$55,"✅ APPROVED") -> 0 | D19: =SUMPRODUCT(('ORDER ENTRY'!$D$6:$D$55=$A19)*('ORDER ENTRY'!$K$6:$K$55="✅ APPROVED")*IFERROR(('ORDER ENTRY'!$G$6:$G$55)*1,0)*IFERROR(('ORDER ENTRY'!$F$6:$F$55)*1,0)) -> 0 | E19: =SUMPRODUCT(('ORDER ENTRY'!$D$6:$D$55=$A19)*('ORDER ENTRY'!$K$6:$K$55="✅ APPROVED")*IFERROR(('ORDER ENTRY'!$I$6:$I$55)*1,0)*IFERROR(('ORDER ENTRY'!$F$6:$F$55)*1,0)) -> 0 | F19: =SUMIF('ORDER ENTRY'!$D$6:$D$55,$A19,'ORDER ENTRY'!$L$6:$L$55) -> 0
A20: TOTAL | B20: =SUM(B5:B19) -> 0 | C20: =SUM(C5:C19) -> 0 | D20: =SUMPRODUCT(('ORDER ENTRY'!$D$6:$D$55=$A20)*('ORDER ENTRY'!$K$6:$K$55="✅ APPROVED")*IFERROR(('ORDER ENTRY'!$G$6:$G$55)*1,0)*IFERROR(('ORDER ENTRY'!$F$6:$F$55)*1,0)) -> 0 | E20: =SUMPRODUCT(('ORDER ENTRY'!$D$6:$D$55=$A20)*('ORDER ENTRY'!$K$6:$K$55="✅ APPROVED")*IFERROR(('ORDER ENTRY'!$I$6:$I$55)*1,0)*IFERROR(('ORDER ENTRY'!$F$6:$F$55)*1,0)) -> 0 | F20: =SUM(F5:F19) -> 0

Sheet 📥 CSV IMPORT GUIDE
A1: HOW TO IMPORT YOUR COST CSV
A3: STEP 1 | B3: Open your CSV file in Excel or Notepad to check the column order.
A4: STEP 2 | B4: Make sure your CSV has: Column 1 = Product Code, Column 2 (optional) = Description, then one column per quantity tier (700, 1000, 1500, 2000, 3000, 3500, 4000, 5000, 6000, 8000, 9500, 10000, 12000, 15000, 20000, 30000, 40000, 50000).
A5: STEP 3 | B5: Go to the COST TABLE tab in this file.
A6: STEP 4 | B6: Click cell A4 (first data row, Product Code column).
A7: STEP 5 | B7: Open your CSV, select all data (Ctrl+A), Copy (Ctrl+C).
A8: STEP 6 | B8: Come back to COST TABLE, click A4, and Paste Special → Values Only (Ctrl+Shift+V or right-click → Paste Special → Values).
A9: STEP 7 | B9: If your quantity tier columns don't match exactly, manually adjust the column headers in row 3 of COST TABLE.
A10: STEP 8 | B10: Go to ORDER ENTRY and test: enter a Product Code in col E and a Quantity in col F — the Cost/Unit should auto-populate from the table.
A11: STEP 9 | B11: Enter a Sale Price in col G to see Margin %, Status, and Commission.
A12: STEP 10 | B12: Adjust Min Margin % and Commission % anytime in the SETTINGS tab.
